{
	"registryname": "concreteplant",
    "localizedname": "Concrete Plant",
	
	"color":"607d8b",
	
    "parts": [
        {
            "x": 3,
            "y": 0,
            "z": -4,

            "elements": [
                "immersiveengineering:sheetmetal_slab@8"
            ]
        },
        {
            "x": 3,
            "y": 2,
            "z": -3,
            "elements": [
                "immersiveengineering:storage@8"
            ]
        },
        {
            "x": 7,
            "y": 2,
            "z": -7,
            "elements": [
                "immersiveengineering:storage@8"
            ]
        },
        {
            "x": 5,
            "y": 0,
            "z": -8,

            "elements": [
                "immersiveengineering:sheetmetal_slab@8"
            ]
        },
        {
            "x": 3,
            "y": 0,
            "z": 0,
            "elements": [
                "immersiveengineering:storage@8"
            ]
        },
        {
            "x": 5,
            "y": 2,
            "z": -7,
            "elements": [
                "immersiveengineering:storage@8"
            ]
        },
        {
            "x": 4,
            "y": 0,
            "z": 0,
            "elements": [
                "immersiveengineering:storage@8"
            ]
        },
        {
            "x": 3,
            "y": 0,
            "z": -8,

            "elements": [
                "immersiveengineering:sheetmetal_slab@8"
            ]
        },
        {
            "x": 5,
            "y": 0,
            "z": 0,
            "elements": [
                "immersiveengineering:storage@8"
            ]
        },
        {
            "x": 3,
            "y": 2,
            "z": -7,
            "elements": [
                "immersiveengineering:storage@8"
            ]
        },
        {
            "x": 23,
            "y": 1,
            "z": -7,
            "elements": [
                "immersiveengineering:storage@8"
            ]
        },
        {
            "x": 5,
            "y": -1,
            "z": 0,
            "elements": [
                "immersiveengineering:storage@8"
            ]
        },
        {
            "x": 4,
            "y": -1,
            "z": 0,
            "elements": [
                "modularmachinery:blockoutputbus@1"
            ]
        },
        {
            "x": 3,
            "y": -1,
            "z": 0,
            "elements": [
                "immersiveengineering:storage@8"
            ]
        },
        {
            "x": 5,
            "y": -1,
            "z": -4,

            "elements": [
                "immersiveengineering:sheetmetal_slab@8"
            ]
        },
        {
            "x": 0,
            "y": -1,
            "z": 0,
            "elements": [
                "modularmachinery:blockcasing@0"
            ]
        },
        {
            "x": 4,
            "y": -1,
            "z": -4,

            "elements": [
                "modularmachinery:blockinputbus@1"
            ]
        },
        {
            "x": 5,
            "y": 1,
            "z": -3,
            "elements": [
                "minecraft:glass@0"
            ]
        },
        {
            "x": 0,
            "y": 1,
            "z": 0,
            "elements": [
                "modularmachinery:blockenergyinputhatch@1"
            ]
        },
        {
            "x": 3,
            "y": -1,
            "z": -4,

            "elements": [
                "immersiveengineering:sheetmetal_slab@8"
            ]
        },
        {
            "x": 3,
            "y": 1,
            "z": -3,
            "elements": [
                "minecraft:glass@0"
            ]
        },
        {
            "x": 7,
            "y": 1,
            "z": -7,
            "elements": [
                "immersiveengineering:storage@8"
            ]
        },
        {
            "x": 5,
            "y": -1,
            "z": -8,

            "elements": [
                "immersiveengineering:sheetmetal_slab@8"
            ]
        },
        {
            "x": 4,
            "y": -1,
            "z": -8,

            "elements": [
                "modularmachinery:blockinputbus@1"
            ]
        },
        {
            "x": 5,
            "y": 1,
            "z": -7,
            "elements": [
                "minecraft:glass@0"
            ]
        },
        {
            "x": 3,
            "y": -1,
            "z": -8,

            "elements": [
                "immersiveengineering:sheetmetal_slab@8"
            ]
        },
        {
            "x": 3,
            "y": 1,
            "z": -7,
            "elements": [
                "minecraft:glass@0"
            ]
        },
        {
            "x": 23,
            "y": 2,
            "z": -2,
            "elements": [
                "immersiveengineering:storage@8"
            ]
        },
        {
            "x": 23,
            "y": 0,
            "z": -7,
            "elements": [
                "immersiveengineering:storage@8"
            ]
        },
        {
            "x": 7,
            "y": 2,
            "z": -2,
            "elements": [
                "immersiveengineering:storage@8"
            ]
        },
        {
            "x": 5,
            "y": 0,
            "z": -3,

            "elements": [
                "immersiveengineering:sheetmetal_slab@8"
            ]
        },
        {
            "x": 5,
            "y": 2,
            "z": -2,
            "elements": [
                "immersiveengineering:storage@8"
            ]
        },
        {
            "x": 3,
            "y": 0,
            "z": -3,

            "elements": [
                "immersiveengineering:sheetmetal_slab@8"
            ]
        },
        {
            "x": 7,
            "y": 0,
            "z": -7,
            "elements": [
                "immersiveengineering:storage@8"
            ]
        },
        {
            "x": 3,
            "y": 2,
            "z": -2,
            "elements": [
                "immersiveengineering:storage@8"
            ]
        },
        {
            "x": 5,
            "y": 0,
            "z": -7,

            "elements": [
                "immersiveengineering:sheetmetal_slab@8"
            ]
        },
        {
            "x": 5,
            "y": 2,
            "z": -6,
            "elements": [
                "immersiveengineering:storage@8"
            ]
        },
        {
            "x": 3,
            "y": 0,
            "z": -7,

            "elements": [
                "immersiveengineering:sheetmetal_slab@8"
            ]
        },
        {
            "x": 3,
            "y": 2,
            "z": -6,
            "elements": [
                "immersiveengineering:storage@8"
            ]
        },
        {
            "x": 23,
            "y": 1,
            "z": -2,
            "elements": [
                "immersiveengineering:storage@8"
            ]
        },
        {
            "x": 23,
            "y": -1,
            "z": -7,
            "elements": [
                "immersiveengineering:storage@8"
            ]
        },
        {
            "x": 22,
            "y": -1,
            "z": -7,
            "elements": [
                "modularmachinery:blockcasing@0"
            ]
        },
        {
            "x": 21,
            "y": -1,
            "z": -7,
            "elements": [
                "modularmachinery:blockcasing@0"
            ]
        },
        {
            "x": 20,
            "y": -1,
            "z": -7,
            "elements": [
                "modularmachinery:blockcasing@0"
            ]
        },
        {
            "x": 19,
            "y": -1,
            "z": -7,
            "elements": [
                "modularmachinery:blockcasing@0"
            ]
        },
        {
            "x": 18,
            "y": -1,
            "z": -7,
            "elements": [
                "modularmachinery:blockcasing@0"
            ]
        },
        {
            "x": 17,
            "y": -1,
            "z": -7,
            "elements": [
                "modularmachinery:blockcasing@0"
            ]
        },
        {
            "x": 16,
            "y": -1,
            "z": -7,
            "elements": [
                "modularmachinery:blockcasing@0"
            ]
        },
        {
            "x": 15,
            "y": -1,
            "z": -7,
            "elements": [
                "modularmachinery:blockcasing@0"
            ]
        },
        {
            "x": 14,
            "y": -1,
            "z": -7,
            "elements": [
                "modularmachinery:blockcasing@0"
            ]
        },
        {
            "x": 13,
            "y": -1,
            "z": -7,
            "elements": [
                "modularmachinery:blockcasing@0"
            ]
        },
        {
            "x": 12,
            "y": -1,
            "z": -7,
            "elements": [
                "modularmachinery:blockcasing@0"
            ]
        },
        {
            "x": 11,
            "y": -1,
            "z": -7,
            "elements": [
                "modularmachinery:blockcasing@0"
            ]
        },
        {
            "x": 7,
            "y": 1,
            "z": -2,
            "elements": [
                "immersiveengineering:storage@8"
            ]
        },
        {
            "x": 10,
            "y": -1,
            "z": -7,
            "elements": [
                "modularmachinery:blockcasing@0"
            ]
        },
        {
            "x": 5,
            "y": -1,
            "z": -3,

            "elements": [
                "immersiveengineering:sheetmetal_slab@8"
            ]
        },
        {
            "x": 9,
            "y": -1,
            "z": -7,
            "elements": [
                "modularmachinery:blockcasing@0"
            ]
        },
        {
            "x": 4,
            "y": -1,
            "z": -3,

            "elements": [
                "modularmachinery:blockinputbus@1"
            ]
        },
        {
            "x": 5,
            "y": 1,
            "z": -2,
            "elements": [
                "immersiveengineering:storage@8"
            ]
        },
        {
            "x": 8,
            "y": -1,
            "z": -7,
            "elements": [
                "modularmachinery:blockcasing@0"
            ]
        },
        {
            "x": 3,
            "y": -1,
            "z": -3,

            "elements": [
                "immersiveengineering:sheetmetal_slab@8"
            ]
        },
        {
            "x": 7,
            "y": -1,
            "z": -7,
            "elements": [
                "immersiveengineering:storage@8"
            ]
        },
        {
            "x": 3,
            "y": 1,
            "z": -2,
            "elements": [
                "immersiveengineering:storage@8"
            ]
        },
        {
            "x": 5,
            "y": -1,
            "z": -7,

            "elements": [
                "immersiveengineering:sheetmetal_slab@8"
            ]
        },
        {
            "x": 4,
            "y": -1,
            "z": -7,

            "elements": [
                "modularmachinery:blockinputbus@1"
            ]
        },
        {
            "x": 5,
            "y": 1,
            "z": -6,
            "elements": [
                "minecraft:glass@0"
            ]
        },
        {
            "x": 3,
            "y": -1,
            "z": -7,

            "elements": [
                "immersiveengineering:sheetmetal_slab@8"
            ]
        },
        {
            "x": 3,
            "y": 1,
            "z": -6,
            "elements": [
                "minecraft:glass@0"
            ]
        },
        {
            "x": 23,
            "y": 0,
            "z": -2,
            "elements": [
                "immersiveengineering:storage@8"
            ]
        },
        {
            "x": 16,
            "y": 0,
            "z": -2,
            "elements": [
                "immersiveengineering:storage@8"
            ]
        },
        {
            "x": 15,
            "y": 0,
            "z": -2,
            "elements": [
                "immersiveengineering:storage@8"
            ]
        },
        {
            "x": 14,
            "y": 0,
            "z": -2,
            "elements": [
                "immersiveengineering:storage@8"
            ]
        },
        {
            "x": 7,
            "y": 0,
            "z": -2,
            "elements": [
                "immersiveengineering:storage@8"
            ]
        },
        {
            "x": 5,
            "y": 0,
            "z": -2,
            "elements": [
                "immersiveengineering:storage@8"
            ]
        },
        {
            "x": 4,
            "y": 0,
            "z": -2,

            "elements": [
                "immersiveengineering:sheetmetal_slab@8"
            ]
        },
        {
            "x": 3,
            "y": 0,
            "z": -2,
            "elements": [
                "immersiveengineering:storage@8"
            ]
        },
        {
            "x": 5,
            "y": 0,
            "z": -6,

            "elements": [
                "immersiveengineering:sheetmetal_slab@8"
            ]
        },
        {
            "x": 5,
            "y": 2,
            "z": -5,
            "elements": [
                "immersiveengineering:storage@8"
            ]
        },
        {
            "x": 3,
            "y": 0,
            "z": -6,

            "elements": [
                "immersiveengineering:sheetmetal_slab@8"
            ]
        },
        {
            "x": 3,
            "y": 2,
            "z": -5,
            "elements": [
                "immersiveengineering:storage@8"
            ]
        },
        {
            "x": 5,
            "y": 2,
            "z": -9,
            "elements": [
                "immersiveengineering:storage@8"
            ]
        },
        {
            "x": 4,
            "y": 2,
            "z": -9,
            "elements": [
                "immersiveengineering:storage@8"
            ]
        },
        {
            "x": 3,
            "y": 2,
            "z": -9,
            "elements": [
                "immersiveengineering:storage@8"
            ]
        },
        {
            "x": 23,
            "y": -1,
            "z": -2,
            "elements": [
                "immersiveengineering:storage@8"
            ]
        },
        {
            "x": 22,
            "y": -1,
            "z": -2,
            "elements": [
                "modularmachinery:blockcasing@0"
            ]
        },
        {
            "x": 21,
            "y": -1,
            "z": -2,
            "elements": [
                "modularmachinery:blockcasing@0"
            ]
        },
        {
            "x": 20,
            "y": -1,
            "z": -2,
            "elements": [
                "modularmachinery:blockcasing@0"
            ]
        },
        {
            "x": 19,
            "y": -1,
            "z": -2,
            "elements": [
                "modularmachinery:blockcasing@0"
            ]
        },
        {
            "x": 18,
            "y": -1,
            "z": -2,
            "elements": [
                "modularmachinery:blockcasing@0"
            ]
        },
        {
            "x": 17,
            "y": -1,
            "z": -2,
            "elements": [
                "modularmachinery:blockcasing@0"
            ]
        },
        {
            "x": 16,
            "y": -1,
            "z": -2,
            "elements": [
                "immersiveengineering:storage@8"
            ]
        },
        {
            "x": 14,
            "y": -1,
            "z": -2,
            "elements": [
                "immersiveengineering:storage@8"
            ]
        },
        {
            "x": 13,
            "y": -1,
            "z": -2,
            "elements": [
                "modularmachinery:blockcasing@0"
            ]
        },
        {
            "x": 12,
            "y": -1,
            "z": -2,
            "elements": [
                "modularmachinery:blockcasing@0"
            ]
        },
        {
            "x": 11,
            "y": -1,
            "z": -2,
            "elements": [
                "modularmachinery:blockcasing@0"
            ]
        },
        {
            "x": 10,
            "y": -1,
            "z": -2,
            "elements": [
                "modularmachinery:blockcasing@0"
            ]
        },
        {
            "x": 9,
            "y": -1,
            "z": -2,
            "elements": [
                "modularmachinery:blockcasing@0"
            ]
        },
        {
            "x": 8,
            "y": -1,
            "z": -2,
            "elements": [
                "modularmachinery:blockcasing@0"
            ]
        },
        {
            "x": 7,
            "y": -1,
            "z": -2,
            "elements": [
                "immersiveengineering:storage@8"
            ]
        },
        {
            "x": 5,
            "y": -1,
            "z": -2,
            "elements": [
                "immersiveengineering:storage@8"
            ]
        },
        {
            "x": 4,
            "y": -1,
            "z": -2,
            "elements": [
                "modularmachinery:blockcasing@0"
            ]
        },
        {
            "x": 3,
            "y": -1,
            "z": -2,
            "elements": [
                "immersiveengineering:storage@8"
            ]
        },
        {
            "x": 5,
            "y": -1,
            "z": -6,

            "elements": [
                "immersiveengineering:sheetmetal_slab@8"
            ]
        },
        {
            "x": 4,
            "y": -1,
            "z": -6,

            "elements": [
                "modularmachinery:blockinputbus@1"
            ]
        },
        {
            "x": 5,
            "y": 1,
            "z": -5,
            "elements": [
                "minecraft:glass@0"
            ]
        },
        {
            "x": 3,
            "y": -1,
            "z": -6,

            "elements": [
                "immersiveengineering:sheetmetal_slab@8"
            ]
        },
        {
            "x": 3,
            "y": 1,
            "z": -5,
            "elements": [
                "minecraft:glass@0"
            ]
        },
        {
            "x": 5,
            "y": 1,
            "z": -9,
            "elements": [
                "immersiveengineering:storage@8"
            ]
        },
        {
            "x": 3,
            "y": 1,
            "z": -9,
            "elements": [
                "immersiveengineering:storage@8"
            ]
        },
        {
            "x": 5,
            "y": 0,
            "z": -5,

            "elements": [
                "immersiveengineering:sheetmetal_slab@8"
            ]
        },
        {
            "x": 5,
            "y": 2,
            "z": -4,
            "elements": [
                "immersiveengineering:storage@8"
            ]
        },
        {
            "x": 3,
            "y": 0,
            "z": -5,

            "elements": [
                "immersiveengineering:sheetmetal_slab@8"
            ]
        },
        {
            "x": 3,
            "y": 2,
            "z": -4,
            "elements": [
                "immersiveengineering:storage@8"
            ]
        },
        {
            "x": 5,
            "y": 0,
            "z": -9,
            "elements": [
                "immersiveengineering:storage@8"
            ]
        },
        {
            "x": 5,
            "y": 2,
            "z": -8,
            "elements": [
                "immersiveengineering:storage@8"
            ]
        },
        {
            "x": 4,
            "y": 0,
            "z": -9,

            "elements": [
                "immersiveengineering:sheetmetal_slab@8"
            ]
        },
        {
            "x": 3,
            "y": 0,
            "z": -9,
            "elements": [
                "immersiveengineering:storage@8"
            ]
        },
        {
            "x": 3,
            "y": 2,
            "z": -8,
            "elements": [
                "immersiveengineering:storage@8"
            ]
        },
        {
            "x": 5,
            "y": -1,
            "z": -1,

            "elements": [
                "immersiveengineering:sheetmetal_slab@8"
            ]
        },
        {
            "x": 4,
            "y": -1,
            "z": -1,
            "elements": [
                "modularmachinery:blockcasing@0"
            ]
        },
        {
            "x": 3,
            "y": -1,
            "z": -1,

            "elements": [
                "immersiveengineering:sheetmetal_slab@8"
            ]
        },
        {
            "x": 5,
            "y": -1,
            "z": -5,

            "elements": [
                "immersiveengineering:sheetmetal_slab@8"
            ]
        },
        {
            "x": 4,
            "y": -1,
            "z": -5,

            "elements": [
                "modularmachinery:blockinputbus@1"
            ]
        },
        {
            "x": 5,
            "y": 1,
            "z": -4,
            "elements": [
                "minecraft:glass@0"
            ]
        },
        {
            "x": 3,
            "y": -1,
            "z": -5,

            "elements": [
                "immersiveengineering:sheetmetal_slab@8"
            ]
        },
        {
            "x": 3,
            "y": 1,
            "z": -4,
            "elements": [
                "minecraft:glass@0"
            ]
        },
        {
            "x": 5,
            "y": -1,
            "z": -9,
            "elements": [
                "immersiveengineering:storage@8"
            ]
        },
        {
            "x": 4,
            "y": -1,
            "z": -9,

            "elements": [
                "immersiveengineering:sheetmetal_slab@8"
            ]
        },
        {
            "x": 5,
            "y": 1,
            "z": -8,
            "elements": [
                "minecraft:glass@0"
            ]
        },
        {
            "x": 3,
            "y": -1,
            "z": -9,
            "elements": [
                "immersiveengineering:storage@8"
            ]
        },
        {
            "x": 3,
            "y": 1,
            "z": -8,
            "elements": [
                "minecraft:glass@0"
            ]
        },
        {
            "x": 23,
            "y": 2,
            "z": -7,
            "elements": [
                "immersiveengineering:storage@8"
            ]
        },
        {
            "x": 5,
            "y": 0,
            "z": -4,

            "elements": [
                "immersiveengineering:sheetmetal_slab@8"
            ]
        },
        {
            "x": 5,
            "y": 2,
            "z": -3,
            "elements": [
                "immersiveengineering:storage@8"
            ]
        }
    ]}